Traceback (most recent call last):
  File "/home/software/apps/local/lib/py38_new/lib/python3.8/site-packages/pandas/core/indexes/datetimes.py", line 718, in slice_indexer
    return Index.slice_indexer(self, start, end, step, kind=kind)
  File "/home/software/apps/local/lib/py38_new/lib/python3.8/site-packages/pandas/core/indexes/base.py", line 4960, in slice_indexer
    start_slice, end_slice = self.slice_locs(start, end, step=step, kind=kind)
  File "/home/software/apps/local/lib/py38_new/lib/python3.8/site-packages/pandas/core/indexes/base.py", line 5161, in slice_locs
    start_slice = self.get_slice_bound(start, "left", kind)
  File "/home/software/apps/local/lib/py38_new/lib/python3.8/site-packages/pandas/core/indexes/base.py", line 5073, in get_slice_bound
    label = self._maybe_cast_slice_bound(label, side, kind)
  File "/home/software/apps/local/lib/py38_new/lib/python3.8/site-packages/pandas/core/indexes/datetimes.py", line 665, in _maybe_cast_slice_bound
    lower, upper = self._parsed_string_to_bounds(reso, parsed)
  File "/home/software/apps/local/lib/py38_new/lib/python3.8/site-packages/pandas/core/indexes/datetimes.py", line 536, in _parsed_string_to_bounds
    raise KeyError
KeyError

During handling of the above exception, another exception occurred:

Traceback (most recent call last):
  File "1_read_data.py", line 268, in <module>
    mms_df_resampled = mms_df_resampled['2017-12-26 06:23:42.664':]
  File "/home/software/apps/local/lib/py38_new/lib/python3.8/site-packages/pandas/core/frame.py", line 2878, in __getitem__
    indexer = convert_to_index_sliceable(self, key)
  File "/home/software/apps/local/lib/py38_new/lib/python3.8/site-packages/pandas/core/indexing.py", line 2134, in convert_to_index_sliceable
    return idx._convert_slice_indexer(key, kind="getitem")
  File "/home/software/apps/local/lib/py38_new/lib/python3.8/site-packages/pandas/core/indexes/base.py", line 3184, in _convert_slice_indexer
    indexer = self.slice_indexer(start, stop, step, kind=kind)
  File "/home/software/apps/local/lib/py38_new/lib/python3.8/site-packages/pandas/core/indexes/datetimes.py", line 728, in slice_indexer
    start_casted = self._maybe_cast_slice_bound(start, "left", kind)
  File "/home/software/apps/local/lib/py38_new/lib/python3.8/site-packages/pandas/core/indexes/datetimes.py", line 665, in _maybe_cast_slice_bound
    lower, upper = self._parsed_string_to_bounds(reso, parsed)
  File "/home/software/apps/local/lib/py38_new/lib/python3.8/site-packages/pandas/core/indexes/datetimes.py", line 536, in _parsed_string_to_bounds
    raise KeyError
KeyError
