Traceback (most recent call last):
  File "2_process_data.py", line 263, in <module>
    psp_inputs_test_list) = mag_interval_pipeline_split(psp_df,
  File "2_process_data.py", line 84, in mag_interval_pipeline_split
    plt.plot(inputs_list_raw[0])
  File "/home/software/apps/local/lib/py38_new/lib/python3.8/site-packages/matplotlib/pyplot.py", line 2823, in plot
    return gca().plot(
  File "/home/software/apps/local/lib/py38_new/lib/python3.8/site-packages/matplotlib/pyplot.py", line 2351, in gca
    return gcf().gca(**kwargs)
  File "/home/software/apps/local/lib/py38_new/lib/python3.8/site-packages/matplotlib/pyplot.py", line 730, in gcf
    return figure()
  File "/home/software/apps/local/lib/py38_new/lib/python3.8/site-packages/matplotlib/pyplot.py", line 670, in figure
    figManager = new_figure_manager(num, figsize=figsize,
  File "/home/software/apps/local/lib/py38_new/lib/python3.8/site-packages/matplotlib/pyplot.py", line 298, in new_figure_manager
    return _backend_mod.new_figure_manager(*args, **kwargs)
  File "/home/software/apps/local/lib/py38_new/lib/python3.8/site-packages/matplotlib/backend_bases.py", line 3490, in new_figure_manager
    return cls.new_figure_manager_given_figure(num, fig)
  File "/home/software/apps/local/lib/py38_new/lib/python3.8/site-packages/matplotlib/backends/_backend_tk.py", line 859, in new_figure_manager_given_figure
    window = tk.Tk(className="matplotlib")
  File "/home/software/apps/python/3.8.1/lib/python3.8/tkinter/__init__.py", line 2261, in __init__
    self.tk = _tkinter.create(screenName, baseName, className, interactive, wantobjects, useTk, sync, use)
_tkinter.TclError: couldn't connect to display "localhost:17.0"
